Workbook

Sheet Dashboard
B12: Australia | G12: =_xlfn.XLOOKUP($B$12,qry_Master_Clean__2[Country],qry_Master_Clean__2[GDP per Capita (US$)]) -> 64595.588 | M12: =_xlfn.XLOOKUP($B$12,qry_Master_Clean__2[Country],qry_Master_Clean__2[Emissions Per Capita (tonnes per person)]) -> 14.218102 | S12: {=_xlfn.XLOOKUP($B$12,qry_Master_Clean__2[Country],qry_Master_Clean__2[Renewalble]/100)} -> 0.123
B103: What-If Analysis:
B104: Current Renewable Share | G104: 0.286
B105: Increase (%) | G105: +10 percentage points
B106: New Renewable Share | G106: 0.386
B107: Cuarrent CO₂ per Capita | G107: =Calculations!B4 -> 3.7043236 | H107: tonnes/person
B108: Estimated CO₂ per Capita | G108: =(-0.0958 * 38.6 + 7.2488) -> 3.55092 | H108: tonnes/person
B109: Estimated CO₂ Reduction | G109: =(G108-G107) -> -0.15340355 | H109: tonnes/person

Sheet qry_Master_Clean (2)
A1: Country | B1: Population_Millions | C1: GDP_Billions | D1: Land_Area_Sq_Km | E1: Energy_QuadBTU | F1: CO2_Tonnes | G1: GDP per Capita (US$) | H1: Energy Consumption per Capita (QuadBTU per million people) | I1: Income Group | J1: CO₂ Tonnes per Billion GDP | K1: Renewalble | L1: Emissions Per Capita (tonnes per person) | N1: CO₂ Emissions (Tonnes per US$1 Billion GDP)
A2: Afghanistan | B2: 42.6 | C2: 17.2 | D2: 652230 | E2: 0.13461777 | F2: 10825998 | G2: =(qry_Master_Clean__2[[#This Row],[GDP_Billions]]*1000/qry_Master_Clean__2[[#This Row],[Population_Millions]]) -> 403.75587 | H2: =IF(qry_Master_Clean__2[[#This Row],[Population_Millions]]=0,"",qry_Master_Clean__2[[#This Row],[Energy_QuadBTU]]/qry_Master_Clean__2[[#This Row],[Population_Millions]]) -> 0.0031600415 | I2: =_xlfn.XLOOKUP(qry_Master_Clean__2[[#This Row],[Country]],Metadata!$E:$E,Metadata!$C:$C,"Not Found") -> Low income | J2: =(F2/C2) -> 629418.49 | K2: =_xlfn.XLOOKUP( qry_Master_Clean__2[[#This Row],[Country]], Renewable!$A$2:$A$267, Renewable!$BN$2:$BN$267, "" ) -> 20 | L2: =qry_Master_Clean__2[[#This Row],[CO2_Tonnes]]/(qry_Master_Clean__2[[#This Row],[Population_Millions]]*1000000) -> 0.25413141
A3: Albania | B3: 2.4 | C3: 27 | D3: 27400 | E3: 0.087328996 | F3: 4444448 | G3: =(qry_Master_Clean__2[[#This Row],[GDP_Billions]]*1000/qry_Master_Clean__2[[#This Row],[Population_Millions]]) -> 11250 | H3: =IF(qry_Master_Clean__2[[#This Row],[Population_Millions]]=0,"",qry_Master_Clean__2[[#This Row],[Energy_QuadBTU]]/qry_Master_Clean__2[[#This Row],[Population_Millions]]) -> 0.036387082 | I3: =_xlfn.XLOOKUP(qry_Master_Clean__2[[#This Row],[Country]],Metadata!$E:$E,Metadata!$C:$C,"Not Found") -> Upper middle income | J3: =(F3/C3) -> 164609.19 | K3: =_xlfn.XLOOKUP( qry_Master_Clean__2[[#This Row],[Country]], Renewable!$A$2:$A$267, Renewable!$BN$2:$BN$267, "" ) -> 41.9 | L3: =qry_Master_Clean__2[[#This Row],[CO2_Tonnes]]/(qry_Master_Clean__2[[#This Row],[Population_Millions]]*1000000) -> 1.8518533
A4: Algeria | B4: 46.8 | C4: 269.3 | D4: 2381740 | E4: 2.8879649 | F4: 198203180 | G4: =(qry_Master_Clean__2[[#This Row],[GDP_Billions]]*1000/qry_Master_Clean__2[[#This Row],[Population_Millions]]) -> 5754.2735 | H4: =IF(qry_Master_Clean__2[[#This Row],[Population_Millions]]=0,"",qry_Master_Clean__2[[#This Row],[Energy_QuadBTU]]/qry_Master_Clean__2[[#This Row],[Population_Millions]]) -> 0.061708652 | I4: =_xlfn.XLOOKUP(qry_Master_Clean__2[[#This Row],[Country]],Metadata!$E:$E,Metadata!$C:$C,"Not Found") -> Upper middle income | J4: =(F4/C4) -> 735993.98 | K4: =_xlfn.XLOOKUP( qry_Master_Clean__2[[#This Row],[Country]], Renewable!$A$2:$A$267, Renewable!$BN$2:$BN$267, "" ) -> 0.1 | L4: =qry_Master_Clean__2[[#This Row],[CO2_Tonnes]]/(qry_Master_Clean__2[[#This Row],[Population_Millions]]*1000000) -> 4.2351107
A5: American Samoa | B5: 0 | C5: 0.9 | D5: 200 | E5: 0.0079105991 | F5: 0 | G5: =(qry_Master_Clean__2[[#This Row],[GDP_Billions]]*1000/qry_Master_Clean__2[[#This Row],[Population_Millions]]) -> #DIV/0! | H5: =IF(qry_Master_Clean__2[[#This Row],[Population_Millions]]=0,"",qry_Master_Clean__2[[#This Row],[Energy_QuadBTU]]/qry_Master_Clean__2[[#This Row],[Population_Millions]]) | I5: =_xlfn.XLOOKUP(qry_Master_Clean__2[[#This Row],[Country]],Metadata!$E:$E,Metadata!$C:$C,"Not Found") -> High income | J5: =(qry_Master_Clean__2[[#This Row],[CO2_Tonnes]]/(qry_Master_Clean__2[[#This Row],[GDP_Billions]]/1000000000)) -> 0 | K5: =_xlfn.XLOOKUP( qry_Master_Clean__2[[#This Row],[Country]], Renewable!$A$2:$A$267, Renewable!$BN$2:$BN$267, "" ) -> 0.4 | L5: =qry_Master_Clean__2[[#This Row],[CO2_Tonnes]]/(qry_Master_Clean__2[[#This Row],[Population_Millions]]*1000000) -> #DIV/0!
A6: Andorra | B6: 0.1 | C6: 4 | D6: 470 | E6: 0 | F6: 424663 | G6: =(qry_Master_Clean__2[[#This Row],[GDP_Billions]]*1000/qry_Master_Clean__2[[#This Row],[Population_Millions]]) -> 40000 | H6: =IF(qry_Master_Clean__2[[#This Row],[Population_Millions]]=0,"",qry_Master_Clean__2[[#This Row],[Energy_QuadBTU]]/qry_Master_Clean__2[[#This Row],[Population_Millions]]) -> 0 | I6: =_xlfn.XLOOKUP(qry_Master_Clean__2[[#This Row],[Country]],Metadata!$E:$E,Metadata!$C:$C,"Not Found") -> High income | J6: =(F6/C6) -> 106165.75 | K6: =_xlfn.XLOOKUP( qry_Master_Clean__2[[#This Row],[Country]], Renewable!$A$2:$A$267, Renewable!$BN$2:$BN$267, "" ) -> 18.4 | L6: =qry_Master_Clean__2[[#This Row],[CO2_Tonnes]]/(qry_Master_Clean__2[[#This Row],[Population_Millions]]*1000000) -> 4.24663
A7: Angola | B7: 37.9 | C7: 101 | D7: 1246700 | E7: 0.34382359 | F7: 22333584 | G7: =(qry_Master_Clean__2[[#This Row],[GDP_Billions]]*1000/qry_Master_Clean__2[[#This Row],[Population_Millions]]) -> 2664.9077 | H7: =IF(qry_Master_Clean__2[[#This Row],[Population_Millions]]=0,"",qry_Master_Clean__2[[#This Row],[Energy_QuadBTU]]/qry_Master_Clean__2[[#This Row],[Population_Millions]]) -> 0.0090718625 | I7: =_xlfn.XLOOKUP(qry_Master_Clean__2[[#This Row],[Country]],Metadata!$E:$E,Metadata!$C:$C,"Not Found") -> Lower middle income | J7: =(F7/C7) -> 221124.59 | K7: =_xlfn.XLOOKUP( qry_Master_Clean__2[[#This Row],[Country]], Renewable!$A$2:$A$267, Renewable!$BN$2:$BN$267, "" ) -> 52.9 | L7: =qry_Master_Clean__2[[#This Row],[CO2_Tonnes]]/(qry_Master_Clean__2[[#This Row],[Population_Millions]]*1000000) -> 0.58927662
A8: Antigua and Barbuda | B8: 0.1 | C8: 2.2 | D8: 440 | E8: 0.010637457 | F8: 665140 | G8: =(qry_Master_Clean__2[[#This Row],[GDP_Billions]]*1000/qry_Master_Clean__2[[#This Row],[Population_Millions]]) -> 22000 | H8: =IF(qry_Master_Clean__2[[#This Row],[Population_Millions]]=0,"",qry_Master_Clean__2[[#This Row],[Energy_QuadBTU]]/qry_Master_Clean__2[[#This Row],[Population_Millions]]) -> 0.10637457 | I8: =_xlfn.XLOOKUP(qry_Master_Clean__2[[#This Row],[Country]],Metadata!$E:$E,Metadata!$C:$C,"Not Found") -> High income | J8: =(F8/C8) -> 302336.36 | K8: =_xlfn.XLOOKUP( qry_Master_Clean__2[[#This Row],[Country]], Renewable!$A$2:$A$267, Renewable!$BN$2:$BN$267, "" ) -> 0.9 | L8: =qry_Master_Clean__2[[#This Row],[CO2_Tonnes]]/(qry_Master_Clean__2[[#This Row],[Population_Millions]]*1000000) -> 6.6514
A9: Argentina | B9: 45.7 | C9: 638.4 | D9: 2736690 | E9: 3.565998 | F9: 171059260 | G9: =(qry_Master_Clean__2[[#This Row],[GDP_Billions]]*1000/qry_Master_Clean__2[[#This Row],[Population_Millions]]) -> 13969.365 | H9: =IF(qry_Master_Clean__2[[#This Row],[Population_Millions]]=0,"",qry_Master_Clean__2[[#This Row],[Energy_QuadBTU]]/qry_Master_Clean__2[[#This Row],[Population_Millions]]) -> 0.078030591 | I9: =_xlfn.XLOOKUP(qry_Master_Clean__2[[#This Row],[Country]],Metadata!$E:$E,Metadata!$C:$C,"Not Found") -> Upper middle income | J9: =(F9/C9) -> 267949.97 | K9: =_xlfn.XLOOKUP( qry_Master_Clean__2[[#This Row],[Country]], Renewable!$A$2:$A$267, Renewable!$BN$2:$BN$267, "" ) -> 9.2 | L9: =qry_Master_Clean__2[[#This Row],[CO2_Tonnes]]/(qry_Master_Clean__2[[#This Row],[Population_Millions]]*1000000) -> 3.743091
A10: Armenia | B10: 3 | C10: 26 | D10: 28197 | E10: 0.16985684 | F10: 7430715 | G10: =(qry_Master_Clean__2[[#This Row],[GDP_Billions]]*1000/qry_Master_Clean__2[[#This Row],[Population_Millions]]) -> 8666.6667 | H10: =IF(qry_Master_Clean__2[[#This Row],[Population_Millions]]=0,"",qry_Master_Clean__2[[#This Row],[Energy_QuadBTU]]/qry_Master_Clean__2[[#This Row],[Population_Millions]]) -> 0.056618947 | I10: =_xlfn.XLOOKUP(qry_Master_Clean__2[[#This Row],[Country]],Metadata!$E:$E,Metadata!$C:$C,"Not Found") -> Upper middle income | J10: =(F10/C10) -> 285796.73 | K10: =_xlfn.XLOOKUP( qry_Master_Clean__2[[#This Row],[Country]], Renewable!$A$2:$A$267, Renewable!$BN$2:$BN$267, "" ) -> 9.1 | L10: =qry_Master_Clean__2[[#This Row],[CO2_Tonnes]]/(qry_Master_Clean__2[[#This Row],[Population_Millions]]*1000000) -> 2.476905
A11: Aruba | B11: 0.1 | C11: 4.3 | D11: 180 | E11: 0.016806703 | F11: 920644 | G11: =(qry_Master_Clean__2[[#This Row],[GDP_Billions]]*1000/qry_Master_Clean__2[[#This Row],[Population_Millions]]) -> 43000 | H11: =IF(qry_Master_Clean__2[[#This Row],[Population_Millions]]=0,"",qry_Master_Clean__2[[#This Row],[Energy_QuadBTU]]/qry_Master_Clean__2[[#This Row],[Population_Millions]]) -> 0.16806703 | I11: =_xlfn.XLOOKUP(qry_Master_Clean__2[[#This Row],[Country]],Metadata!$E:$E,Metadata!$C:$C,"Not Found") -> High income | J11: =(F11/C11) -> 214103.26 | K11: =_xlfn.XLOOKUP( qry_Master_Clean__2[[#This Row],[Country]], Renewable!$A$2:$A$267, Renewable!$BN$2:$BN$267, "" ) -> 8.8 | L11: =qry_Master_Clean__2[[#This Row],[CO2_Tonnes]]/(qry_Master_Clean__2[[#This Row],[Population_Millions]]*1000000) -> 9.20644
A12: Australia | B12: 27.2 | C12: 1757 | D12: 7692020 | E12: 5.9926708 | F12: 386732380 | G12: =(qry_Master_Clean__2[[#This Row],[GDP_Billions]]*1000/qry_Master_Clean__2[[#This Row],[Population_Millions]]) -> 64595.588 | H12: =IF(qry_Master_Clean__2[[#This Row],[Population_Millions]]=0,"",qry_Master_Clean__2[[#This Row],[Energy_QuadBTU]]/qry_Master_Clean__2[[#This Row],[Population_Millions]]) -> 0.22031878 | I12: =_xlfn.XLOOKUP(qry_Master_Clean__2[[#This Row],[Country]],Metadata!$E:$E,Metadata!$C:$C,"Not Found") -> High income | J12: =(F12/C12) -> 220109.49 | K12: =_xlfn.XLOOKUP( qry_Master_Clean__2[[#This Row],[Country]], Renewable!$A$2:$A$267, Renewable!$BN$2:$BN$267, "" ) -> 12.3 | L12: =qry_Master_Clean__2[[#This Row],[CO2_Tonnes]]/(qry_Master_Clean__2[[#This Row],[Population_Millions]]*1000000) -> 14.218102
A13: Austria | B13: 9.2 | C13: 534.8 | D13: 82520 | E13: 1.0674109 | F13: 56367656 | G13: =(qry_Master_Clean__2[[#This Row],[GDP_Billions]]*1000/qry_Master_Clean__2[[#This Row],[Population_Millions]]) -> 58130.435 | H13: =IF(qry_Master_Clean__2[[#This Row],[Population_Millions]]=0,"",qry_Master_Clean__2[[#This Row],[Energy_QuadBTU]]/qry_Master_Clean__2[[#This Row],[Population_Millions]]) -> 0.11602293 | I13: =_xlfn.XLOOKUP(qry_Master_Clean__2[[#This Row],[Country]],Metadata!$E:$E,Metadata!$C:$C,"Not Found") -> High income | J13: =(F13/C13) -> 105399.51 | K13: =_xlfn.XLOOKUP( qry_Master_Clean__2[[#This Row],[Country]], Renewable!$A$2:$A$267, Renewable!$BN$2:$BN$267, "" ) -> 36 | L13: =qry_Master_Clean__2[[#This Row],[CO2_Tonnes]]/(qry_Master_Clean__2[[#This Row],[Population_Millions]]*1000000) -> 6.1269191
A14: Azerbaijan | B14: 10.2 | C14: 74.3 | D14: 82650 | E14: 0.65287564 | F14: 39830140 | G14: =(qry_Master_Clean__2[[#This Row],[GDP_Billions]]*1000/qry_Master_Clean__2[[#This Row],[Population_Millions]]) -> 7284.3137 | H14: =IF(qry_Master_Clean__2[[#This Row],[Population_Millions]]=0,"",qry_Master_Clean__2[[#This Row],[Energy_QuadBTU]]/qry_Master_Clean__2[[#This Row],[Population_Millions]]) -> 0.064007416 | I14: =_xlfn.XLOOKUP(qry_Master_Clean__2[[#This Row],[Country]],Metadata!$E:$E,Metadata!$C:$C,"Not Found") -> Upper middle income | J14: =(F14/C14) -> 536071.87 | K14: =_xlfn.XLOOKUP( qry_Master_Clean__2[[#This Row],[Country]], Renewable!$A$2:$A$267, Renewable!$BN$2:$BN$267, "" ) -> 1.3 | L14: =qry_Master_Clean__2[[#This Row],[CO2_Tonnes]]/(qry_Master_Clean__2[[#This Row],[Population_Millions]]*1000000) -> 3.9049157
A15: Bahamas, The | B15: 0.4 | C15: 15.8 | D15: 10010 | E15: 0 | F15: 0 | G15: =(qry_Master_Clean__2[[#This Row],[GDP_Billions]]*1000/qry_Master_Clean__2[[#This Row],[Population_Millions]]) -> 39500 | H15: =IF(qry_Master_Clean__2[[#This Row],[Population_Millions]]=0,"",qry_Master_Clean__2[[#This Row],[Energy_QuadBTU]]/qry_Master_Clean__2[[#This Row],[Population_Millions]]) -> 0 | I15: =_xlfn.XLOOKUP(qry_Master_Clean__2[[#This Row],[Country]],Metadata!$E:$E,Metadata!$C:$C,"Not Found") -> High income | J15: =(qry_Master_Clean__2[[#This Row],[CO2_Tonnes]]/(qry_Master_Clean__2[[#This Row],[GDP_Billions]]/1000000000)) -> 0 | K15: =_xlfn.XLOOKUP( qry_Master_Clean__2[[#This Row],[Country]], Renewable!$A$2:$A$267, Renewable!$BN$2:$BN$267, "" ) -> 1.1 | L15: =qry_Master_Clean__2[[#This Row],[CO2_Tonnes]]/(qry_Master_Clean__2[[#This Row],[Population_Millions]]*1000000) -> 0
A16: Bahrain | B16: 1.6 | C16: 47.1 | D16: 790 | E16: 0.8337039 | F16: 39003456 | G16: =(qry_Master_Clean__2[[#This Row],[GDP_Billions]]*1000/qry_Master_Clean__2[[#This Row],[Population_Millions]]) -> 29437.5 | H16: =IF(qry_Master_Clean__2[[#This Row],[Population_Millions]]=0,"",qry_Master_Clean__2[[#This Row],[Energy_QuadBTU]]/qry_Master_Clean__2[[#This Row],[Population_Millions]]) -> 0.52106494 | I16: =_xlfn.XLOOKUP(qry_Master_Clean__2[[#This Row],[Country]],Metadata!$E:$E,Metadata!$C:$C,"Not Found") -> High income | J16: =(F16/C16) -> 828098.85 | K16: =_xlfn.XLOOKUP( qry_Master_Clean__2[[#This Row],[Country]], Renewable!$A$2:$A$267, Renewable!$BN$2:$BN$267, "" ) -> 0 | L16: =qry_Master_Clean__2[[#This Row],[CO2_Tonnes]]/(qry_Master_Clean__2[[#This Row],[Population_Millions]]*1000000) -> 24.37716
A17: Korea, Dem. People's Rep. | B17: 26.5 | C17: 0 | D17: 120410 | E17: 0 | F17: 0 | G17: =(qry_Master_Clean__2[[#This Row],[GDP_Billions]]*1000/qry_Master_Clean__2[[#This Row],[Population_Millions]]) -> 0 | H17: =IF(qry_Master_Clean__2[[#This Row],[Population_Millions]]=0,"",qry_Master_Clean__2[[#This Row],[Energy_QuadBTU]]/qry_Master_Clean__2[[#This Row],[Population_Millions]]) -> 0 | I17: =_xlfn.XLOOKUP(qry_Master_Clean__2[[#This Row],[Country]],Metadata!$E:$E,Metadata!$C:$C,"Not Found") -> Low income | J17: =(qry_Master_Clean__2[[#This Row],[CO2_Tonnes]]/(qry_Master_Clean__2[[#This Row],[GDP_Billions]]/1000000000)) -> #DIV/0! | K17: =_xlfn.XLOOKUP( qry_Master_Clean__2[[#This Row],[Country]], Renewable!$A$2:$A$267, Renewable!$BN$2:$BN$267, "" ) -> 14.7 | L17: =qry_Master_Clean__2[[#This Row],[CO2_Tonnes]]/(qry_Master_Clean__2[[#This Row],[Population_Millions]]*1000000) -> 0
A18: Bangladesh | B18: 173.6 | C18: 450.1 | D18: 130170 | E18: 1.9686078 | F18: 108317880 | G18: =(qry_Master_Clean__2[[#This Row],[GDP_Billions]]*1000/qry_Master_Clean__2[[#This Row],[Population_Millions]]) -> 2592.7419 | H18: =IF(qry_Master_Clean__2[[#This Row],[Population_Millions]]=0,"",qry_Master_Clean__2[[#This Row],[Energy_QuadBTU]]/qry_Master_Clean__2[[#This Row],[Population_Millions]]) -> 0.011339906 | I18: =_xlfn.XLOOKUP(qry_Master_Clean__2[[#This Row],[Country]],Metadata!$E:$E,Metadata!$C:$C,"Not Found") -> Lower middle income | J18: =(F18/C18) -> 240652.92 | K18: =_xlfn.XLOOKUP( qry_Master_Clean__2[[#This Row],[Country]], Renewable!$A$2:$A$267, Renewable!$BN$2:$BN$267, "" ) -> 25 | L18: =qry_Master_Clean__2[[#This Row],[CO2_Tonnes]]/(qry_Master_Clean__2[[#This Row],[Population_Millions]]*1000000) -> 0.62395092
A19: Barbados | B19: 0.3 | C19: 7.5 | D19: 430 | E19: 0.023098936 | F19: 1365171 | G19: =(qry_Master_Clean__2[[#This Row],[GDP_Billions]]*1000/qry_Master_Clean__2[[#This Row],[Population_Millions]]) -> 25000 | H19: =IF(qry_Master_Clean__2[[#This Row],[Population_Millions]]=0,"",qry_Master_Clean__2[[#This Row],[Energy_QuadBTU]]/qry_Master_Clean__2[[#This Row],[Population_Millions]]) -> 0.076996454 | I19: =_xlfn.XLOOKUP(qry_Master_Clean__2[[#This Row],[Country]],Metadata!$E:$E,Metadata!$C:$C,"Not Found") -> High income | J19: =(F19/C19) -> 182022.8 | K19: =_xlfn.XLOOKUP( qry_Master_Clean__2[[#This Row],[Country]], Renewable!$A$2:$A$267, Renewable!$BN$2:$BN$267, "" ) -> 5.5 | L19: =qry_Master_Clean__2[[#This Row],[CO2_Tonnes]]/(qry_Master_Clean__2[[#This Row],[Population_Millions]]*1000000) -> 4.55057
A20: Belarus | B20: 9.1 | C20: 76 | D20: 202950 | E20: 0.99457682 | F20: 55818416 | G20: =(qry_Master_Clean__2[[#This Row],[GDP_Billions]]*1000/qry_Master_Clean__2[[#This Row],[Population_Millions]]) -> 8351.6484 | H20: =IF(qry_Master_Clean__2[[#This Row],[Population_Millions]]=0,"",qry_Master_Clean__2[[#This Row],[Energy_QuadBTU]]/qry_Master_Clean__2[[#This Row],[Population_Millions]]) -> 0.10929416 | I20: =_xlfn.XLOOKUP(qry_Master_Clean__2[[#This Row],[Country]],Metadata!$E:$E,Metadata!$C:$C,"Not Found") -> Upper middle income | J20: =(F20/C20) -> 734452.84 | K20: =_xlfn.XLOOKUP( qry_Master_Clean__2[[#This Row],[Country]], Renewable!$A$2:$A$267, Renewable!$BN$2:$BN$267, "" ) -> 8.2 | L20: =qry_Master_Clean__2[[#This Row],[CO2_Tonnes]]/(qry_Master_Clean__2[[#This Row],[Population_Millions]]*1000000) -> 6.1338919
A21: Belgium | B21: 11.9 | C21: 671.4 | D21: 30494 | E21: 2.2828087 | F21: 85456200 | G21: =(qry_Master_Clean__2[[#This Row],[GDP_Billions]]*1000/qry_Master_Clean__2[[#This Row],[Population_Millions]]) -> 56420.168 | H21: =IF(qry_Master_Clean__2[[#This Row],[Population_Millions]]=0,"",qry_Master_Clean__2[[#This Row],[Energy_QuadBTU]]/qry_Master_Clean__2[[#This Row],[Population_Millions]]) -> 0.19183266 | I21: =_xlfn.XLOOKUP(qry_Master_Clean__2[[#This Row],[Country]],Metadata!$E:$E,Metadata!$C:$C,"Not Found") -> High income | J21: =(F21/C21) -> 127280.61 | K21: =_xlfn.XLOOKUP( qry_Master_Clean__2[[#This Row],[Country]], Renewable!$A$2:$A$267, Renewable!$BN$2:$BN$267, "" ) -> 11.7 | L21: =qry_Master_Clean__2[[#This Row],[CO2_Tonnes]]/(qry_Master_Clean__2[[#This Row],[Population_Millions]]*1000000) -> 7.1811933
A22: Belize | B22: 0.4 | C22: 3.2 | D22: 22810 | E22: 0.014390815 | F22: 796027 | G22: =(qry_Master_Clean__2[[#This Row],[GDP_Billions]]*1000/qry_Master_Clean__2[[#This Row],[Population_Millions]]) -> 8000 | H22: =IF(qry_Master_Clean__2[[#This Row],[Population_Millions]]=0,"",qry_Master_Clean__2[[#This Row],[Energy_QuadBTU]]/qry_Master_Clean__2[[#This Row],[Population_Millions]]) -> 0.035977038 | I22: =_xlfn.XLOOKUP(qry_Master_Clean__2[[#This Row],[Country]],Metadata!$E:$E,Metadata!$C:$C,"Not Found") -> Upper middle income | J22: =(F22/C22) -> 248758.44 | K22: =_xlfn.XLOOKUP( qry_Master_Clean__2[[#This Row],[Country]], Renewable!$A$2:$A$267, Renewable!$BN$2:$BN$267, "" ) -> 26.6 | L22: =qry_Master_Clean__2[[#This Row],[CO2_Tonnes]]/(qry_Master_Clean__2[[#This Row],[Population_Millions]]*1000000) -> 1.9900675
A23: Benin | B23: 14.5 | C23: 21.5 | D23: 112760 | E23: 0.10717695 | F23: 6066339 | G23: =(qry_Master_Clean__2[[#This Row],[GDP_Billions]]*1000/qry_Master_Clean__2[[#This Row],[Population_Millions]]) -> 1482.7586 | H23: =IF(qry_Master_Clean__2[[#This Row],[Population_Millions]]=0,"",qry_Master_Clean__2[[#This Row],[Energy_QuadBTU]]/qry_Master_Clean__2[[#This Row],[Population_Millions]]) -> 0.0073915136 | I23: =_xlfn.XLOOKUP(qry_Master_Clean__2[[#This Row],[Country]],Metadata!$E:$E,Metadata!$C:$C,"Not Found") -> Lower middle income | J23: =(F23/C23) -> 282155.3 | K23: =_xlfn.XLOOKUP( qry_Master_Clean__2[[#This Row],[Country]], Renewable!$A$2:$A$267, Renewable!$BN$2:$BN$267, "" ) -> 54.5 | L23: =qry_Master_Clean__2[[#This Row],[CO2_Tonnes]]/(qry_Master_Clean__2[[#This Row],[Population_Millions]]*1000000) -> 0.41836821
A24: Bermuda | B24: 0.1 | C24: 9.2 | D24: 54 | E24: 0.0082251094 | F24: 550001 | G24: =(qry_Master_Clean__2[[#This Row],[GDP_Billions]]*1000/qry_Master_Clean__2[[#This Row],[Population_Millions]]) -> 92000 | H24: =IF(qry_Master_Clean__2[[#This Row],[Population_Millions]]=0,"",qry_Master_Clean__2[[#This Row],[Energy_QuadBTU]]/qry_Master_Clean__2[[#This Row],[Population_Millions]]) -> 0.082251094 | I24: =_xlfn.XLOOKUP(qry_Master_Clean__2[[#This Row],[Country]],Metadata!$E:$E,Metadata!$C:$C,"Not Found") -> High income | J24: =(F24/C24) -> 59782.717 | K24: =_xlfn.XLOOKUP( qry_Master_Clean__2[[#This Row],[Country]], Renewable!$A$2:$A$267, Renewable!$BN$2:$BN$267, "" ) -> 0.9 | L24: =qry_Master_Clean__2[[#This Row],[CO2_Tonnes]]/(qry_Master_Clean__2[[#This Row],[Population_Millions]]*1000000) -> 5.50001
A25: Bhutan | B25: 0.8 | C25: 3 | D25: 38140 | E25: 0.060721214 | F25: 1657416 | G25: =(qry_Master_Clean__2[[#This Row],[GDP_Billions]]*1000/qry_Master_Clean__2[[#This Row],[Population_Millions]]) -> 3750 | H25: =IF(qry_Master_Clean__2[[#This Row],[Population_Millions]]=0,"",qry_Master_Clean__2[[#This Row],[Energy_QuadBTU]]/qry_Master_Clean__2[[#This Row],[Population_Millions]]) -> 0.075901518 | I25: =_xlfn.XLOOKUP(qry_Master_Clean__2[[#This Row],[Country]],Metadata!$E:$E,Metadata!$C:$C,"Not Found") -> Lower middle income | J25: =(F25/C25) -> 552472 | K25: =_xlfn.XLOOKUP( qry_Master_Clean__2[[#This Row],[Country]], Renewable!$A$2:$A$267, Renewable!$BN$2:$BN$267, "" ) -> 81.8 | L25: =qry_Master_Clean__2[[#This Row],[CO2_Tonnes]]/(qry_Master_Clean__2[[#This Row],[Population_Millions]]*1000000) -> 2.07177
A26: Bolivia | B26: 12.4 | C26: 54.9 | D26: 1083300 | E26: 0.39731764 | F26: 28708664 | G26: =(qry_Master_Clean__2[[#This Row],[GDP_Billions]]*1000/qry_Master_Clean__2[[#This Row],[Population_Millions]]) -> 4427.4194 | H26: =IF(qry_Master_Clean__2[[#This Row],[Population_Millions]]=0,"",qry_Master_Clean__2[[#This Row],[Energy_QuadBTU]]/qry_Master_Clean__2[[#This Row],[Population_Millions]]) -> 0.032041745 | I26: =_xlfn.XLOOKUP(qry_Master_Clean__2[[#This Row],[Country]],Metadata!$E:$E,Metadata!$C:$C,"Not Found") -> Lower middle income | J26: =(F26/C26) -> 522926.48 | K26: =_xlfn.XLOOKUP( qry_Master_Clean__2[[#This Row],[Country]], Renewable!$A$2:$A$267, Renewable!$BN$2:$BN$267, "" ) -> 12.8 | L26: =qry_Master_Clean__2[[#This Row],[CO2_Tonnes]]/(qry_Master_Clean__2[[#This Row],[Population_Millions]]*1000000) -> 2.3152148
A27: Bosnia and Herzegovina | B27: 3.2 | C27: 29.6 | D27: 51200 | E27: 0.29860538 | F27: 19425932 | G27: =(qry_Master_Clean__2[[#This Row],[GDP_Billions]]*1000/qry_Master_Clean__2[[#This Row],[Population_Millions]]) -> 9250 | H27: =IF(qry_Master_Clean__2[[#This Row],[Population_Millions]]=0,"",qry_Master_Clean__2[[#This Row],[Energy_QuadBTU]]/qry_Master_Clean__2[[#This Row],[Population_Millions]]) -> 0.093314182 | I27: =_xlfn.XLOOKUP(qry_Master_Clean__2[[#This Row],[Country]],Metadata!$E:$E,Metadata!$C:$C,"Not Found") -> Upper middle income | J27: =(F27/C27) -> 656281.49 | K27: =_xlfn.XLOOKUP( qry_Master_Clean__2[[#This Row],[Country]], Renewable!$A$2:$A$267, Renewable!$BN$2:$BN$267, "" ) -> 36.6 | L27: =qry_Master_Clean__2[[#This Row],[CO2_Tonnes]]/(qry_Master_Clean__2[[#This Row],[Population_Millions]]*1000000) -> 6.0706038
A28: Botswana | B28: 2.5 | C28: 19.4 | D28: 566730 | E28: 0.084397061 | F28: 7461599 | G28: =(qry_Master_Clean__2[[#This Row],[GDP_Billions]]*1000/qry_Master_Clean__2[[#This Row],[Population_Millions]]) -> 7760 | H28: =IF(qry_Master_Clean__2[[#This Row],[Population_Millions]]=0,"",qry_Master_Clean__2[[#This Row],[Energy_QuadBTU]]/qry_Master_Clean__2[[#This Row],[Population_Millions]]) -> 0.033758824 | I28: =_xlfn.XLOOKUP(qry_Master_Clean__2[[#This Row],[Country]],Metadata!$E:$E,Metadata!$C:$C,"Not Found") -> Upper middle income | J28: =(F28/C28) -> 384618.51 | K28: =_xlfn.XLOOKUP( qry_Master_Clean__2[[#This Row],[Country]], Renewable!$A$2:$A$267, Renewable!$BN$2:$BN$267, "" ) -> 27.4 | L28: =qry_Master_Clean__2[[#This Row],[CO2_Tonnes]]/(qry_Master_Clean__2[[#This Row],[Population_Millions]]*1000000) -> 2.9846396
A29: Brazil | B29: 212 | C29: 2185.8 | D29: 8358140 | E29: 10.686541 | F29: 483011550 | G29: =(qry_Master_Clean__2[[#This Row],[GDP_Billions]]*1000/qry_Master_Clean__2[[#This Row],[Population_Millions]]) -> 10310.377 | H29: =IF(qry_Master_Clean__2[[#This Row],[Population_Millions]]=0,"",qry_Master_Clean__2[[#This Row],[Energy_QuadBTU]]/qry_Master_Clean__2[[#This Row],[Population_Millions]]) -> 0.050408213 | I29: =_xlfn.XLOOKUP(qry_Master_Clean__2[[#This Row],[Country]],Metadata!$E:$E,Metadata!$C:$C,"Not Found") -> Upper middle income | J29: =(F29/C29) -> 220977.01 | K29: =_xlfn.XLOOKUP( qry_Master_Clean__2[[#This Row],[Country]], Renewable!$A$2:$A$267, Renewable!$BN$2:$BN$267, "" ) -> 46.5 | L29: =qry_Master_Clean__2[[#This Row],[CO2_Tonnes]]/(qry_Master_Clean__2[[#This Row],[Population_Millions]]*1000000) -> 2.2783564
A30: Brunei Darussalam | B30: 0.5 | C30: 15.3 | D30: 5270 | E30: 0 | F30: 0 | G30: =(qry_Master_Clean__2[[#This Row],[GDP_Billions]]*1000/qry_Master_Clean__2[[#This Row],[Population_Millions]]) -> 30600 | H30: =IF(qry_Master_Clean__2[[#This Row],[Population_Millions]]=0,"",qry_Master_Clean__2[[#This Row],[Energy_QuadBTU]]/qry_Master_Clean__2[[#This Row],[Population_Millions]]) -> 0 | I30: =_xlfn.XLOOKUP(qry_Master_Clean__2[[#This Row],[Country]],Metadata!$E:$E,Metadata!$C:$C,"Not Found") -> High income | J30: =(qry_Master_Clean__2[[#This Row],[CO2_Tonnes]]/(qry_Master_Clean__2[[#This Row],[GDP_Billions]]/1000000000)) -> 0 | K30: =_xlfn.XLOOKUP( qry_Master_Clean__2[[#This Row],[Country]], Renewable!$A$2:$A$267, Renewable!$BN$2:$BN$267, "" ) -> 0 | L30: =qry_Master_Clean__2[[#This Row],[CO2_Tonnes]]/(qry_Master_Clean__2[[#This Row],[Population_Millions]]*1000000) -> 0
A31: Bulgaria | B31: 6.4 | C31: 113.3 | D31: 108560 | E31: 0.64979131 | F31: 31621824 | G31: =(qry_Master_Clean__2[[#This Row],[GDP_Billions]]*1000/qry_Master_Clean__2[[#This Row],[Population_Millions]]) -> 17703.125 | H31: =IF(qry_Master_Clean__2[[#This Row],[Population_Millions]]=0,"",qry_Master_Clean__2[[#This Row],[Energy_QuadBTU]]/qry_Master_Clean__2[[#This Row],[Population_Millions]]) -> 0.10152989 | I31: =_xlfn.XLOOKUP(qry_Master_Clean__2[[#This Row],[Country]],Metadata!$E:$E,Metadata!$C:$C,"Not Found") -> High income | J31: =(F31/C31) -> 279098.18 | K31: =_xlfn.XLOOKUP( qry_Master_Clean__2[[#This Row],[Country]], Renewable!$A$2:$A$267, Renewable!$BN$2:$BN$267, "" ) -> 20.4 | L31: =qry_Master_Clean__2[[#This Row],[CO2_Tonnes]]/(qry_Master_Clean__2[[#This Row],[Population_Millions]]*1000000) -> 4.94091
A32: Burkina Faso | B32: 23.5 | C32: 23.1 | D32: 273600 | E32: 0.085374167 | F32: 6507663 | G32: =(qry_Master_Clean__2[[#This Row],[GDP_Billions]]*1000/qry_Master_Clean__2[[#This Row],[Population_Millions]]) -> 982.97872 | H32: =IF(qry_Master_Clean__2[[#This Row],[Population_Millions]]=0,"",qry_Master_Clean__2[[#This Row],[Energy_QuadBTU]]/qry_Master_Clean__2[[#This Row],[Population_Millions]]) -> 0.0036329433 | I32: =_xlfn.XLOOKUP(qry_Master_Clean__2[[#This Row],[Country]],Metadata!$E:$E,Metadata!$C:$C,"Not Found") -> Low income | J32: =(F32/C32) -> 281717.01 | K32: =_xlfn.XLOOKUP( qry_Master_Clean__2[[#This Row],[Country]], Renewable!$A$2:$A$267, Renewable!$BN$2:$BN$267, "" ) -> 71.2 | L32: =qry_Master_Clean__2[[#This Row],[CO2_Tonnes]]/(qry_Master_Clean__2[[#This Row],[Population_Millions]]*1000000) -> 0.27692183
A33: Burundi | B33: 14 | C33: 3.1 | D33: 25680 | E33: 0.013341732 | F33: 916664 | G33: =(qry_Master_Clean__2[[#This Row],[GDP_Billions]]*1000/qry_Master_Clean__2[[#This Row],[Population_Millions]]) -> 221.42857 | H33: =IF(qry_Master_Clean__2[[#This Row],[Population_Millions]]=0,"",qry_Master_Clean__2[[#This Row],[Energy_QuadBTU]]/qry_Master_Clean__2[[#This Row],[Population_Millions]]) -> 0.00095298086 | I33: =_xlfn.XLOOKUP(qry_Master_Clean__2[[#This Row],[Country]],Metadata!$E:$E,Metadata!$C:$C,"Not Found") -> Low income | J33: =(F33/C33) -> 295698.06 | K33: =_xlfn.XLOOKUP( qry_Master_Clean__2[[#This Row],[Country]], Renewable!$A$2:$A$267, Renewable!$BN$2:$BN$267, "" ) -> 83.1 | L33: =qry_Master_Clean__2[[#This Row],[CO2_Tonnes]]/(qry_Master_Clean__2[[#This Row],[Population_Millions]]*1000000) -> 0.065476
A34: Cabo Verde | B34: 0.5 | C34: 2.7 | D34: 4030 | E34: 0.010623084 | F34: 0 | G34: =(qry_Master_Clean__2[[#This Row],[GDP_Billions]]*1000/qry_Master_Clean__2[[#This Row],[Population_Millions]]) -> 5400 | H34: =IF(qry_Master_Clean__2[[#This Row],[Population_Millions]]=0,"",qry_Master_Clean__2[[#This Row],[Energy_QuadBTU]]/qry_Master_Clean__2[[#This Row],[Population_Millions]]) -> 0.021246169 | I34: =_xlfn.XLOOKUP(qry_Master_Clean__2[[#This Row],[Country]],Metadata!$E:$E,Metadata!$C:$C,"Not Found") -> Upper middle income | J34: =(qry_Master_Clean__2[[#This Row],[CO2_Tonnes]]/(qry_Master_Clean__2[[#This Row],[GDP_Billions]]/1000000000)) -> 0 | K34: =_xlfn.XLOOKUP( qry_Master_Clean__2[[#This Row],[Country]], Renewable!$A$2:$A$267, Renewable!$BN$2:$BN$267, "" ) -> 22.6 | L34: =qry_Master_Clean__2[[#This Row],[CO2_Tonnes]]/(qry_Master_Clean__2[[#This Row],[Population_Millions]]*1000000) -> 0
A35: Cambodia | B35: 17.6 | C35: 46.4 | D35: 176520 | E35: 0.29900285 | F35: 21882690 | G35: =(qry_Master_Clean__2[[#This Row],[GDP_Billions]]*1000/qry_Master_Clean__2[[#This Row],[Population_Millions]]) -> 2636.3636 | H35: =IF(qry_Master_Clean__2[[#This Row],[Population_Millions]]=0,"",qry_Master_Clean__2[[#This Row],[Energy_QuadBTU]]/qry_Master_Clean__2[[#This Row],[Population_Millions]]) -> 0.016988799 | I35: =_xlfn.XLOOKUP(qry_Master_Clean__2[[#This Row],[Country]],Metadata!$E:$E,Metadata!$C:$C,"Not Found") -> Lower middle income | J35: =(F35/C35) -> 471609.7 | K35: =_xlfn.XLOOKUP( qry_Master_Clean__2[[#This Row],[Country]], Renewable!$A$2:$A$267, Renewable!$BN$2:$BN$267, "" ) -> 52.4 | L35: =qry_Master_Clean__2[[#This Row],[CO2_Tonnes]]/(qry_Master_Clean__2[[#This Row],[Population_Millions]]*1000000) -> 1.2433347
A36: Yemen, Rep. | B36: 40.6 | C36: 0 | D36: 527970 | E36: 0 | F36: 0 | G36: =(qry_Master_Clean__2[[#This Row],[GDP_Billions]]*1000/qry_Master_Clean__2[[#This Row],[Population_Millions]]) -> 0 | H36: =IF(qry_Master_Clean__2[[#This Row],[Population_Millions]]=0,"",qry_Master_Clean__2[[#This Row],[Energy_QuadBTU]]/qry_Master_Clean__2[[#This Row],[Population_Millions]]) -> 0 | I36: =_xlfn.XLOOKUP(qry_Master_Clean__2[[#This Row],[Country]],Metadata!$E:$E,Metadata!$C:$C,"Not Found") -> Low income | J36: =(qry_Master_Clean__2[[#This Row],[CO2_Tonnes]]/(qry_Master_Clean__2[[#This Row],[GDP_Billions]]/1000000000)) -> #DIV/0! | K36: =_xlfn.XLOOKUP( qry_Master_Clean__2[[#This Row],[Country]], Renewable!$A$2:$A$267, Renewable!$BN$2:$BN$267, "" ) -> 3.7 | L36: =qry_Master_Clean__2[[#This Row],[CO2_Tonnes]]/(qry_Master_Clean__2[[#This Row],[Population_Millions]]*1000000) -> 0
A37: Eritrea | B37: 3.5 | C37: 0 | D37: 121178 | E37: 0.010705254 | F37: 742647 | G37: =(qry_Master_Clean__2[[#This Row],[GDP_Billions]]*1000/qry_Master_Clean__2[[#This Row],[Population_Millions]]) -> 0 | H37: =IF(qry_Master_Clean__2[[#This Row],[Population_Millions]]=0,"",qry_Master_Clean__2[[#This Row],[Energy_QuadBTU]]/qry_Master_Clean__2[[#This Row],[Population_Millions]]) -> 0.0030586439 | I37: =_xlfn.XLOOKUP(qry_Master_Clean__2[[#This Row],[Country]],Metadata!$E:$E,Metadata!$C:$C,"Not Found") -> Low income | J37: =(F37/C37) -> #DIV/0! | K37: =_xlfn.XLOOKUP( qry_Master_Clean__2[[#This Row],[Country]], Renewable!$A$2:$A$267, Renewable!$BN$2:$BN$267, "" ) -> 80.7 | L37: =qry_Master_Clean__2[[#This Row],[CO2_Tonnes]]/(qry_Master_Clean__2[[#This Row],[Population_Millions]]*1000000) -> 0.21218486
A38: South Sudan | B38: 11.9 | C38: 0 | D38: 631930 | E38: 0.024908716 | F38: 1695552 | G38: =(qry_Master_Clean__2[[#This Row],[GDP_Billions]]*1000/qry_Master_Clean__2[[#This Row],[Population_Millions]]) -> 0 | H38: =IF(qry_Master_Clean__2[[#This Row],[Population_Millions]]=0,"",qry_Master_Clean__2[[#This Row],[Energy_QuadBTU]]/qry_Master_Clean__2[[#This Row],[Population_Millions]]) -> 0.0020931694 | I38: =_xlfn.XLOOKUP(qry_Master_Clean__2[[#This Row],[Country]],Metadata!$E:$E,Metadata!$C:$C,"Not Found") -> Low income | J38: =(F38/C38) -> #DIV/0! | K38: =_xlfn.XLOOKUP( qry_Master_Clean__2[[#This Row],[Country]], Renewable!$A$2:$A$267, Renewable!$BN$2:$BN$267, "" ) -> 32.4 | L38: =qry_Master_Clean__2[[#This Row],[CO2_Tonnes]]/(qry_Master_Clean__2[[#This Row],[Population_Millions]]*1000000) -> 0.14248336
A39: Cuba | B39: 11 | C39: 0 | D39: 103800 | E39: 0.28749625 | F39: 24440234 | G39: =(qry_Master_Clean__2[[#This Row],[GDP_Billions]]*1000/qry_Master_Clean__2[[#This Row],[Population_Millions]]) -> 0 | H39: =IF(qry_Master_Clean__2[[#This Row],[Population_Millions]]=0,"",qry_Master_Clean__2[[#This Row],[Energy_QuadBTU]]/qry_Master_Clean__2[[#This Row],[Population_Millions]]) -> 0.026136023 | I39: =_xlfn.XLOOKUP(qry_Master_Clean__2[[#This Row],[Country]],Metadata!$E:$E,Metadata!$C:$C,"Not Found") -> Upper middle income | J39: =(F39/C39) -> #DIV/0! | K39: =_xlfn.XLOOKUP( qry_Master_Clean__2[[#This Row],[Country]], Renewable!$A$2:$A$267, Renewable!$BN$2:$BN$267, "" ) -> 20.9 | L39: =qry_Master_Clean__2[[#This Row],[CO2_Tonnes]]/(qry_Master_Clean__2[[#This Row],[Population_Millions]]*1000000) -> 2.2218395
A40: Cameroon | B40: 29.1 | C40: 53.3 | D40: 472710 | E40: 0.11952242 | F40: 9631583 | G40: =(qry_Master_Clean__2[[#This Row],[GDP_Billions]]*1000/qry_Master_Clean__2[[#This Row],[Population_Millions]]) -> 1831.6151 | H40: =IF(qry_Master_Clean__2[[#This Row],[Population_Millions]]=0,"",qry_Master_Clean__2[[#This Row],[Energy_QuadBTU]]/qry_Master_Clean__2[[#This Row],[Population_Millions]]) -> 0.0041072997 | I40: =_xlfn.XLOOKUP(qry_Master_Clean__2[[#This Row],[Country]],Metadata!$E:$E,Metadata!$C:$C,"Not Found") -> Lower middle income | J40: =(F40/C40) -> 180705.12 | K40: =_xlfn.XLOOKUP( qry_Master_Clean__2[[#This Row],[Country]], Renewable!$A$2:$A$267, Renewable!$BN$2:$BN$267, "" ) -> 79.2 | L40: =qry_Master_Clean__2[[#This Row],[CO2_Tonnes]]/(qry_Master_Clean__2[[#This Row],[Population_Millions]]*1000000) -> 0.33098223
...

Sheet Data_Dictionary
A1: Dataset | B1: Source | C1: Unit | D1: Frequency | E1: Years | F1: Primary Key
A2: Population | B2: World Bank | C2: Millions | D2: Annual | E2: 2020–2024 | F2: Country + Year
A3: GDP | B3: World Bank | C3: Billions USD | D3: Annual | E3: 2015–2024 | F3: Country + Year
A4: Land Area | B4: World Bank | C4: km² | D4: Static | E4: Latest | F4: Country
A5: Energy Consumption | B5: EIA | C5: Quad BTU | D5: Annual | E5: 1980–2024 | F5: Country + Year
A6: CO₂ Emissions | B6: Our World in Data / World Bank | C6: Tonnes | D6: Annual | E6: 1949–2024 | F6: Country + Year

Sheet Audit dataset
A1: Dataset | B1: Rows | C1: Missing Values | D1: Issues
A2: Countries | B2: 214 | C2: 0
A3: Population
A4: GDP | B4: 215 | C4: 4 | D4: Some missing GDP values
A5: Population | B5: 215 | C5: 0 | D5: OK
A6: Energy | B6: 215 | C6: 12 | D6: Missing for some countries
A7: Emissions | B7: 215 | C7: 6 | D7: Country names need checking

Sheet Countries_Population
A1: Country | B1: Population_2000_Millions | C1: Population_2024_Millions | D1: Population_Growth_2000_2024_Pct | E1: Age_0_14_2024_Pct | F1: Age_15_64_2024_Pct | G1: Age_65_Plus_2024_Pct | H1: Dependency_Young_2024_Pct | I1: Dependency_Old_2024_Pct | J1: Death_Rate_2024 | K1: Birth_Rate_2024
A2: Afghanistan | B2: 20.1 | C2: 42.6 | D2: 3.1 | E2: 43 | F2: 55 | G2: 2 | H2: 78 | I2: 4 | J2: 6 | K2: 35
A3: Albania | B3: 3.1 | C3: 2.4 | D3: -1.1 | E3: 17 | F3: 66 | G3: 17 | H3: 25 | I3: 26 | J3: 8 | K3: 10
A4: Algeria | B4: 30.9 | C4: 46.8 | D4: 1.7 | E4: 30 | F4: 63 | G4: 7 | H4: 48 | I4: 10 | J4: 5 | K4: 19
A5: American Samoa | B5: 0.1 | C5: 0 | D5: -0.8 | E5: 27 | F5: 65 | G5: 8 | H5: 42 | I5: 12 | J5: 7 | K5: 15
A6: Andorra | B6: 0.1 | C6: 0.1 | D6: 0.9 | E6: 12 | F6: 72 | G6: 16 | H6: 16 | I6: 22 | J6: 6 | K6: 7
A7: Angola | B7: 16.2 | C7: 37.9 | D7: 3.5 | E7: 44 | F7: 53 | G7: 3 | H7: 84 | I7: 5 | J7: 7 | K7: 37
A8: Antigua and Barbuda | B8: 0.1 | C8: 0.1 | D8: 0.9 | E8: 18 | F8: 70 | G8: 12 | H8: 25 | I8: 17 | J8: 7 | K8: 12
A9: Argentina | B9: 37.2 | C9: 45.7 | D9: 0.9 | E9: 22 | F9: 66 | G9: 12 | H9: 33 | I9: 19 | J9: 8 | K9: 11
A10: Armenia | B10: 3.2 | C10: 3 | D10: -0.3 | E10: 19 | F10: 67 | G10: 14 | H10: 29 | I10: 20 | J10: 8 | K10: 11
A11: Aruba | B11: 0.1 | C11: 0.1 | D11: 0.7 | E11: 17 | F11: 66 | G11: 17 | H11: 25 | I11: 26 | J11: 8 | K11: 8
A12: Australia | B12: 19 | C12: 27.2 | D12: 1.5 | E12: 18 | F12: 64 | G12: 18 | H12: 28 | I12: 28 | J12: 7 | K12: 11
A13: Austria | B13: 8 | C13: 9.2 | D13: 0.6 | E13: 14 | F13: 65 | G13: 21 | H13: 22 | I13: 32 | J13: 10 | K13: 8
... A215: Zimbabwe | B215: 11.9 | C215: 16.6 | D215: 1.4 | E215: 41 | F215: 56 | G215: 4 | H215: 74 | I215: 6 | J215: 7 | K215: 30
A216: =COUNTA(A2:A215) -> 214
A218: World | B218: 6161.9 | C218: 8141.8 | D218: 1.2 | E218: 25 | F218: 65 | G218: 10 | H218: 38 | I218: 16 | J218: 8 | K218: 16
A219: East Asia & Pacific | B219: 2050.1 | C219: 2388.3 | D219: 0.6 | E219: 18 | F219: 68 | G219: 14 | H219: 26 | I219: 20 | J219: 8 | K219: 9
A220: Europe & Central Asia | B220: 865.4 | C220: 928.3 | D220: 0.3 | E220: 17 | F220: 64 | G220: 18 | H220: 27 | I220: 28 | J220: 10 | K220: 10
A221: Latin America & Caribbean | B221: 520.3 | C221: 662.2 | D221: 1 | E221: 23 | F221: 68 | G221: 10 | H221: 33 | I221: 15 | J221: 7 | K221: 14
A222: Middle East, North Africa, Afghanistan & Pakistan | B222: 494.9 | C222: 813.1 | D222: 2.1 | E222: 32 | F222: 63 | G222: 5 | H222: 51 | I222: 8 | J222: 5 | K222: 23
A223: North America | B223: 312.9 | C223: 381.5 | D223: 0.8 | E223: 17 | F223: 65 | G223: 18 | H223: 26 | I223: 28 | J223: 9 | K223: 10
A224: South Asia | B224: 1237.2 | C224: 1677.4 | D224: 1.3 | E224: 25 | F224: 68 | G224: 7 | H224: 37 | I224: 11 | J224: 6 | K224: 16
A225: Sub-Saharan Africa | B225: 681.1 | C225: 1291 | D225: 2.7 | E225: 41 | F225: 56 | G225: 3 | H225: 73 | I225: 6 | J225: 8 | K225: 33
A226: Low income | B226: 322.7 | C226: 624.6 | D226: 2.8 | E226: 42 | F226: 55 | G226: 3 | H226: 75 | I226: 6 | J226: 7 | K226: 35
A227: Lower middle income | B227: 2126.6 | C227: 3121 | D227: 1.6 | E227: 30 | F227: 64 | G227: 6 | H227: 46 | I227: 9 | J227: 7 | K227: 21
A228: Upper middle income | B228: 2365 | C228: 2817.9 | D228: 0.7 | E228: 20 | F228: 68 | G228: 12 | H228: 29 | I228: 18 | J228: 7 | K228: 10
A229: High income | B229: 1255.7 | C229: 1417.8 | D229: 0.5 | E229: 16 | F229: 65 | G229: 20 | H229: 24 | I229: 30 | J229: 10 | K229: 9
A233: Most Recent Value (MRV) if data for the specified year or full period are not available; or growth rate is calculated for less than the full period.
A235: 2.1 Population dynamics
A237: World Development Indicators , THE WORLD BANK
A238: Last updated date 04/08/2026
A240: About the Data
A242: Population, total
A243: Long definition
A244: Total population is based on the de facto definition of population, which counts all residents regardless of legal status or citizenship. The values shown are midyear estimates.
A246: Source
A247: World Population Prospects, United Nations (UN), uri: https://population.un.org/wpp/, publisher: UN Population Division; Statistical databases and publications from national statistical offices, National Statistical Offices, uri: https://unstats.un.org/home/nso_sites/, publisher: National Statistical Offices; Eurostat: Demographic Statistics, Eurostat (ESTAT), uri: https://ec.europa.eu/eurostat/data/database?node_code=earn_ses_monthly, publisher: Eurostat; Population and Vital Statistics Report (various years), United Nations (UN), uri: https://unstats.un.org, publisher: UN Statistics Division
A249: Population ages 0-14 (% of total population)
A250: Long definition
... A299: Please see the online table at http://wdi.worldbank.org/table/2.1 for observation-level metadata, which can be downloaded in Excel.

Sheet Countires_Land
A1: Country | B1: Rural_Population_2022 | C1: Rural__Population_Growth_(Annual_%)_2022 | D1: Land_Area_(Sq_Km)_2021 | E1: Forest_Area__(%_Of_Land_Area)_2021 | F1: Permanent_Cropland_(%_Of_Land_Area)_2021 | G1: Arable_Land_(%_Of_Land_Area)_2021 | H1: Arable_Land_(Hectares_Per_Person)_2021
A2: Afghanistan | B2: 30274.28 | C2: 1.37 | D2: 652230 | E2: 1.85 | F2: 0.41 | G2: 12 | H2: 0.2
A3: Albania | B3: 1033.01 | C3: -2.39 | D3: 27400 | E3: 28.79 | F3: 3.2 | G3: 21.89 | H3: 0.24
A4: Algeria | B4: 11742.45 | C4: -0.56 | D4: 2381740 | E4: 0.82 | F4: 0.39 | G4: 3.16 | H4: 0.17
A5: American Samoa | B5: 8.8 | C5: 0.51 | D5: 200 | E5: 85.5 | F5: 9.65 | G5: 4.85 | H5: 0.02
A6: Andorra | B6: 8.96 | C6: 0.89 | D6: 470 | E6: 34.04 | F6: 0.02 | G6: 1.59 | H6: 0.01
A7: Angola | B7: 11028.82 | C7: 0.6 | D7: 1246700 | E7: 52.98 | F7: 0.25 | G7: 4.29 | H7: 0.15
A8: Antigua and Barbuda | B8: 70.08 | C8: 0.62 | D8: 440 | E8: 18.3 | F8: 2.27 | G8: 9.09 | H8: 0.04
A9: Argentina | B9: 3581.4 | C9: -0.84 | D9: 2736690 | E9: 10.4 | F9: 0.39 | G9: 15.43 | H9: 0.93
A10: Armenia | B10: 1022.52 | C10: -0.36 | D10: 28197.09 | E10: 11.64 | F10: 2.14 | G10: 15.73 | H10: 0.15
A11: Aruba | B11: 40.91 | C11: -0.24 | D11: 180 | E11: 2.33 | F11: .. | G11: 11.11 | H11: 0.02
A12: Australia | B12: 3295.45 | C12: 0.51 | D12: 7692020 | E12: 17.42 | F12: 0.05 | G12: 4.06 | H12: 1.22
A13: Austria | B13: 2803.15 | C13: 0.23 | D13: 82520 | E13: 47.17 | F13: 0.82 | G13: 16.03 | H13: 0.15
A14: Azerbaijan | B14: 4215.09 | C14: -0.13 | D14: 82650 | E14: 13.83 | F14: 3.32 | G14: 25.28 | H14: 0.21
A15: Bahamas, The | B15: 74.26 | C15: 1.14 | D15: 10010 | E15: 50.94 | F15: 0.3 | G15: 0.8 | H15: 0.02
A16: Bahrain | B16: 0 | C16: .. | D16: 790 | E16: 0.91 | F16: 2.53 | G16: 2.66 | H16: 0
A17: Bangladesh | B17: 115734.37 | C17: 0.62 | D17: 130170 | E17: 14.47 | F17: 7.25 | G17: 60.49 | H17: 0.05
A18: Barbados | B18: 114.75 | C18: -0.02 | D18: 430 | E18: 14.65 | F18: 2.33 | G18: 16.28 | H18: 0.02
A19: Belarus | B19: 1986.5 | C19: -2.38 | D19: 202950 | E19: 43.27 | F19: 0.47 | G19: 27.71 | H19: 0.6
A20: Belgium | B20: 1461.29 | C20: 0.34 | D20: 30494 | E20: 22.6 | F20: 0.78 | G20: 28.39 | H20: 0.07
A21: Belize | B21: 233.03 | C21: 2.29 | D21: 22810 | E21: 55.5 | F21: 1.4 | G21: 4.38 | H21: 0.25
A22: Benin | B22: 6747.29 | C22: 1 | D22: 112760 | E22: 27.36 | F22: 5.2 | G22: 30.92 | H22: 0.26
A23: Bermuda | B23: 0 | C23: .. | D23: 54 | E23: 18.52 | F23: .. | G23: 5.56 | H23: 0
A24: Bhutan | B24: 461.24 | C24: -0.36 | D24: 38140 | E24: 71.5 | F24: 0.26 | G24: 2.54 | H24: 0.13
A25: Bolivia | B25: 3546.43 | C25: 0.18 | D25: 1083300 | E25: 46.73 | F25: 0.23 | G25: 4.99 | H25: 0.45
A26: Bosnia and Herzegovina | B26: 1569.66 | C26: -2.32 | D26: 51200 | E26: 42.73 | F26: 2.11 | G26: 19.69 | H26: 0.31
A27: Botswana | B27: 815.19 | C27: 1.38 | D27: 566730 | E27: 26.71 | F27: 0 | G27: 0.46 | H27: 0.11
A28: Brazil | B28: 26604.7 | C28: -1.31 | D28: 8358140 | E28: 59.27 | F28: 0.93 | G28: 6.66 | H28: 0.27
A29: British Virgin Islands | B29: 17.32 | C29: -0.46 | D29: 150 | E29: 24.13 | F29: 6.67 | G29: 6.67 | H29: 0.03
A30: Brunei Darussalam | B30: 114.86 | C30: 0.76 | D30: 5270 | E30: 72.11 | F30: 1.14 | G30: 0.76 | H30: 0.01
A31: Bulgaria | B31: 1714.55 | C31: -1.15 | D31: 108560 | E31: 35.98 | F31: 1.37 | G31: 32.24 | H31: 0.54
A32: Burkina Faso | B32: 16368.77 | C32: 1.67 | D32: 273600 | E32: 22.54 | F32: 2.3 | G32: 28.44 | H32: 0.35
A33: Burundi | B33: 10347.8 | C33: 1.16 | D33: 25680 | E33: 10.89 | F33: 13.63 | G33: 49.45 | H33: 0.1
A34: Cabo Verde | B34: 129.76 | C34: -2.84 | D34: 4030 | E34: 11.42 | F34: 0.99 | G34: 12.41 | H34: 0.1
A35: Cambodia | B35: 10256.59 | C35: 0.89 | D35: 176520 | E35: 44.83 | F35: 2.86 | G35: 23.34 | H35: 0.24
... A37: Canada | B37: 6872.16 | C37: 0.83 | D37: 8788700 | E37: 39.47 | F37: 0.02 | G37: 4.35 | H37: 1
A38: Cayman Islands | B38: 0 | C38: .. | D38: 240 | E38: 52.75 | F38: 2.08 | G38: 0.83 | H38: 0
A39: Central African Republic | B39: 2891.85 | C39: -1.01 | D39: 622980 | E39: 35.75 | F39: 1.32 | G39: 2.89 | H39: 0.35
A40: Chad | B40: 13700.57 | C40: 2.74 | D40: 1259200 | E40: 3.34 | F40: 0.03 | G40: 4.21 | H40: 0.3
A41: Channel Islands | B41: 112.38 | C41: 0.32 | D41: 198 | E41: 5.15 | F41: .. | G41: .. | H41: ..
...

Sheet GDP
A1: Column1 | B1: GDP_$_Billions_2015 | C1: GDP_$ Billions_2024 | D1: Agriculture_% _Of_GDP_2015 | E1: Agriculture_% _Of_GDP_2024 | F1: Industry_% Of GDP_2015 | G1: Industry_% Of GDP_2024 | H1: Manufacturing% Of GDP_2015 | I1: Manufacturing% Of GDP2024 | J1: Services% Of GDP_2015 | K1: Services% Of GDP_2024
A2: Afghanistan | B2: 19.1 | C2: 17.2 | D2: 20.6 | E2: 34.7 | F2: 22.1 | G2: 13.4 | H2: 11.4 | I2: 7.5 | J2: 53.2 | K2: 46.4
A3: Albania | B3: 11.5 | C3: 27 | D3: 18.7 | E3: 15.5 | F3: 24.5 | G3: 22.4 | H3: 6.3 | I3: 6.5 | J3: 42.9 | K3: 48.7
A4: Algeria | B4: 187.5 | C4: 269.3 | D4: 10.5 | E4: 14 | F4: 32.8 | G4: 36.2 | H4: 7.1 | I4: 9.5 | J4: 52.1 | K4: 46.8
A5: American Samoa | B5: 0.7 | C5: 0.9 | D5: .. | E5: .. | F5: .. | G5: .. | H5: .. | I5: .. | J5: .. | K5: ..
A6: Andorra | B6: 2.8 | C6: 4 | D6: 0.5 | E6: 0.5 | F6: 10 | G6: 12.8 | H6: 3.7 | I6: 3.4 | J6: 78.7 | K6: 77.6
A7: Angola | B7: 102.5 | C7: 101 | D7: 13.7 | E7: 22.1 | F7: 36.7 | G7: 34.6 | H7: 5.2 | I7: 7.6 | J7: 48 | K7: 41.1
A8: Antigua and Barbuda | B8: 1.4 | C8: 2.2 | D8: 1.4 | E8: 1.9 | F8: 15.9 | G8: 19 | H8: 2.8 | I8: 2.6 | J8: 73.1 | K8: 69.1
A9: Argentina | B9: 594.7 | C9: 638.4 | D9: 5.2 | E9: 5.8 | F9: 23.2 | G9: 24 | H9: 14.2 | I9: 15.2 | J9: 55.8 | K9: 53.7
A10: Armenia | B10: 10.6 | C10: 26 | D10: 17.2 | E10: 7.8 | F10: 25.7 | G10: 22.9 | H10: 9.2 | I10: 10.2 | J10: 48.2 | K10: 62
A11: Aruba | B11: 3 | C11: 4.3 | D11: 0 | E11: 0 | F11: 12.5 | G11: 9.7 | H11: 3.6 | I11: 2.6 | J11: 79.1 | K11: 79
A12: Australia | B12: 1356.8 | C12: 1757 | D12: 2.4 | E12: 2 | F12: 23.7 | G12: 25.5 | H12: 6.2 | I12: 5.4 | J12: 67.2 | K12: 66.1
A13: Austria | B13: 379.5 | C13: 534.8 | D13: 1.1 | E13: 1.2 | F13: 25.5 | G13: 24.6 | H13: 17.2 | I13: 15.1 | J13: 62.2 | K13: 64
A14: Azerbaijan | B14: 53.1 | C14: 74.3 | D14: 6.2 | E14: 5.7 | F14: 44.9 | G14: 42.6 | H14: 5 | I14: 5.2 | J14: 40.7 | K14: 42.3
A15: Bahamas, The | B15: 11.8 | C15: 15.8 | D15: 0.8 | E15: 0.5 | F15: 11.2 | G15: 9.6 | H15: 2.5 | I15: 0.6 | J15: 76.8 | K15: 77.2
A16: Bahrain | B16: 32.5 | C16: 47.1 | D16: 0.3 | E16: 0.2 | F16: 39.1 | G16: 42.3 | H16: 17.2 | I16: 19.9 | J16: 59.7 | K16: 53.2
A17: Bangladesh | B17: 195.1 | C17: 450.1 | D17: 14.8 | E17: 11.2 | F17: 26.8 | G17: 34.1 | H17: 16.8 | I17: 21.9 | J17: 53.7 | K17: 51.4
... A29: Brunei Darussalam | B29: 12.9 | C29: 15.3 | D29: 1.1 | E29: 1.2 | F29: 61.4 | G29: 61.7 | H29: 1.6 | I29: 10.7 | J29: 39.4 | K29: 39
A30: Bulgaria | B30: 50.8 | C30: 113.3 | D30: 4.1 | E30: 2.4 | F30: 24 | G30: 21.1 | H30: .. | I30: .. | J30: 58.3 | K30: 63.8
A31: Burkina Faso | B31: 11.8 | C31: 23.1 | D31: 22.6 | E31: 20.9 | F31: 24.4 | G31: 26.5 | H31: 11.7 | I31: 9.5 | J31: 44.1 | K31: 43.9
A32: Burundi | B32: 2.8 | C32: 3.1 | D32: 35.2 | E32: 34.9 | F32: 15.4 | G32: 17.7 | H32: 10.9 | I32: 11.5 | J32: 43.4 | K32: 43.2
A33: Cabo Verde | B33: 1.7 | C33: 2.7 | D33: 6.4 | E33: 4.9 | F33: 14.6 | G33: 10.7 | H33: 4.9 | I33: 5.1 | J33: 67.2 | K33: 68.7
A34: Cambodia | B34: 24.2 | C34: 46.4 | D34: 20.1 | E34: 16.6 | F34: 31.5 | G34: 41.8 | H34: 22.5 | I34: 27.8 | J34: 42.2 | K34: 35.6
A35: Cameroon | B35: 32.2 | C35: 53.3 | D35: 17.2 | E35: 18.5 | F35: 25.1 | G35: 23.2 | H35: 14.4 | I35: 12.9 | J35: 49.6 | K35: 50.7
A36: Canada | B36: 1556.5 | C36: 2243.6 | D36: 1.9 | E36: .. | F36: 24.4 | G36: .. | H36: 10 | I36: .. | J36: 67 | K36: ..
A37: Cayman Islands | B37: 4.7 | C37: 7.2 | D37: 0.4 | E37: 0.4 | F37: 7 | G37: 7.8 | H37: 0.8 | I37: 1 | J37: 87.4 | K37: 86
A38: Central African Republic | B38: 1.7 | C38: 2.8 | D38: 31.5 | E38: 27.9 | F38: 22.1 | G38: 20 | H38: 19.7 | I38: 18 | J38: 43.2 | K38: 42.1
A39: Chad | B39: 14.6 | C39: 19.5 | D39: 33.6 | E39: 37.7 | F39: 33.9 | G39: 28.7 | H39: 6.9 | I39: 7.1 | J39: 30.5 | K39: 29.8
A40: Channel Islands | B40: 10.1 | C40: 12.5 | D40: 0.8 | E40: 0.6 | F40: 7.7 | G40: 8.2 | H40: 0.9 | I40: 0.8 | J40: 91.7 | K40: 91.2
A41: Chile | B41: 242.5 | C41: 330.3 | D41: 3.7 | E41: 3.9 | F41: 27.9 | G41: 30.1 | H41: 10.4 | I41: 9 | J41: 58.3 | K41: 56.1
A42: China | B42: 11280.8 | C42: 18743.8 | D42: 8.2 | E42: 6.8 | F42: 40 | G42: 36.5 | H42: 28.4 | I42: 24.9 | J42: 51.7 | K42: 56.7
A43: Hong Kong SAR, China | B43: 309.4 | C43: 406.9 | D43: 0.1 | E43: 0 | F43: 7.1 | G43: 6.2 | H43: 1.1 | I43: 0.9 | J43: 89.8 | K43: 91.8
A44: Macao SAR, China | B44: 44.9 | C44: 49.5 | D44: .. | E44: .. | F44: 7.7 | G44: 5.4 | H44: 0.6 | I44: 0.8 | J44: 91.8 | K44: 90.9
A45: Colombia | B45: 293.5 | C45: 418.8 | D45: 6 | E45: 9.3 | F45: 28.6 | G45: 23.1 | H45: 12.4 | I45: 10.1 | J45: 56.2 | K45: 58.1
A46: Comoros | B46: 1 | C46: 1.4 | D46: 30.6 | E46: 36.6 | F46: 10.4 | G46: 9.6 | H46: .. | I46: .. | J46: 54.9 | K46: 50.1
A47: Congo, Dem. Rep. | B47: 40.2 | C47: 71 | D47: 12.5 | E47: 9.6 | F47: 40.5 | G47: 39.9 | H47: 16.8 | I47: 8.2 | J47: 42.4 | K47: 46.6
A48: Congo, Rep. | B48: 12.4 | C48: 15.7 | D48: 5.8 | E48: 9.4 | F48: 48.7 | G48: 40.1 | H48: 8.4 | I48: .. | J48: 39.2 | K48: 45
A49: Costa Rica | B49: 56.4 | C49: 95.4 | D49: 4.7 | E49: 3.6 | F49: 20 | G49: 19.7 | H49: 11.6 | I49: 13 | J49: 67.3 | K49: 68.8
A50: Cote d'Ivoire | B50: 45.8 | C50: 87.1 | D50: 18.4 | E50: 15.9 | F50: 20.1 | G50: 24 | H50: 11.4 | I50: 12.9 | J50: 54.1 | K50: 51.9
A51: Croatia | B51: 51 | C51: 93 | D51: 3 | E51: 2.9 | F51: 20.4 | G51: 19.2 | H51: 12.7 | I51: 10.5 | J51: 59.3 | K51: 60.8
...

Sheet Energy Consumption
A1: Report generated on: 06-27-2026 20:37:11
A2: API_Code | B2: Energy_Type | C2: 1980 | D2: 1981 | E2: 1982 | F2: 1983 | G2: 1984 | H2: 1985 | I2: 1986 | J2: 1987 | K2: 1988 | L2: 1989 | M2: 1990 | N2: 1991 | O2: 1992 | P2: 1993 | Q2: 1994 | R2: 1995 | S2: 1996 | T2: 1997 | U2: 1998 | V2: 1999 | W2: 2000 | X2: 2001 | Y2: 2002 | Z2: 2003 | AA2: 2004 | AB2: 2005 | AC2: 2006 | AD2: 2007 | AE2: 2008 | AF2: 2009 | AG2: 2010 | AH2: 2011 | AI2: 2012 | AJ2: 2013 | AK2: 2014 | AL2: 2015 | AM2: 2016 | AN2: 2017 | AO2: 2018 | AP2: 2019 | AQ2: 2020 | AR2: 2021 | AS2: 2022 | AT2: 2023 | AU2: 2024
B3: Afghanistan
A4: INTL.44-2-AFG-QBTU.A | B4: Consumption (quad Btu) | C4: 0.021623379 | D4: 0.024872997 | E4: 0.026919218 | F4: 0.033719327 | G4: 0.033882152 | H4: 0.03285812 | I4: 0.034096058 | J4: 0.057767973 | K4: 0.10607836 | L4: 0.10409964 | M4: 0.10303601 | N4: 0.042640902 | O4: 0.028003943 | P4: 0.02782721 | Q4: 0.026857007 | R4: 0.022505732 | S4: 0.022359263 | T4: 0.021483512 | U4: 0.021004098 | V4: 0.02098328 | W4: 0.018042878 | X4: 0.012450843 | Y4: 0.011357232 | Z4: 0.013540179 | AA4: 0.012682489 | AB4: 0.017109714 | AC4: 0.022283409 | AD4: 0.026472342 | AE4: 0.0513188 | AF4: 0.08618441 | AG4: 0.1100194 | AH4: 0.14123299 | AI4: 0.13314562 | AJ4: 0.10874241 | AK4: 0.090866072 | AL4: 0.10561779 | AM4: 0.095797059 | AN4: 0.12460259 | AO4: 0.15863904 | AP4: 0.16075122 | AQ4: 0.16006951 | AR4: 0.16231321 | AS4: 0.1539092 | AT4: 0.13744602 | AU4: 0.13461777
A5: INTL.4411-2-AFG-QBTU.A | B5: Coal (quad Btu) | C5: 0.0024792482 | D5: 0.0026042524 | E5: 0.0030209328 | F5: 0.0030209328 | G5: 0.0030834348 | H5: 0.0031459369 | I5: 0.0033334431 | J5: 0.0034792812 | K5: 0.0028750947 | L5: 0.0026459203 | M5: 0.0021875719 | N5: 0.0019583978 | O5: 0.00016667213 | P5: 0.00014583814 | Q5: 0.00012500415 | R5: 0.00010417016 | S5: 6.250198e-05 | T5: 4.1667986e-05 | U5: 4.1667986e-05 | V5: 2.0833993e-05 | W5: 2.0833993e-05 | X5: 0.00054168458 | Y5: 0.00043751442 | Z5: 0.00072919071 | AA5: 0.00070835671 | AB5: 0.00068752253 | AC5: 0.00072919071 | AD5: 0.0021212492 | AE5: 0.0035133077 | AF5: 0.0061791981 | AG5: 0.010345138 | AH5: 0.013110956 | AI5: 0.015876774 | AJ5: 0.017724885 | AK5: 0.014260951 | AL5: 0.013874091 | AM5: 0.019768281 | AN5: 0.021566236 | AO5: 0.023364191 | AP5: 0.025162146 | AQ5: 0.020746989 | AR5: 0.034876105 | AS5: 0.030549208 | AT5: 0.009931516 | AU5: 0.0056170529
A6: INTL.4413-2-AFG-QBTU.A | B6: Natural gas (quad Btu) | C6: 0.002094 | D6: 0.003141 | E6: 0.005235 | F6: 0.005235 | G6: 0.005235 | H6: 0 | I6: 0 | J6: 0.023034 | K6: 0.07329 | L6: 0.071196 | M6: 0.070150672 | N6: 0.011517 | O6: 0.011092441 | P6: 0.011092441 | Q6: 0.01108773 | R6: 0.00739182 | S6: 0.0085042051 | T6: 0.0085042051 | U6: 0.0085042051 | V6: 0.0085042051 | W6: 0.0085042051 | X6: 0.0018487403 | Y6: 0.0018487403 | Z6: 0.0007394961 | AA6: 0.0007394961 | AB6: 0.0007394961 | AC6: 0.0007394961 | AD6: 0.0014789922 | AE6: 0.0018487403 | AF6: 0.0011092441 | AG6: 0.0052466803 | AH6: 0.0059676828 | AI6: 0.0059270109 | AJ6: 0.0057125588 | AK6: 0.0052466803 | AL6: 0.0054056706 | AM6: 0.0061118833 | AN6: 0.0061118833 | AO6: 0.0059983378 | AP6: 0.0050390736 | AQ6: 0.003140122 | AR6: NA | AS6: NA | AT6: NA | AU6: NA
A7: INTL.4415-2-AFG-QBTU.A | B7: Petroleum and other liquids (quad Btu) | C7: 0.014624098 | D7: 0.01666759 | E7: 0.016250901 | F7: 0.022917937 | G7: 0.022980726 | H7: 0.027084834 | I7: 0.028329758 | J7: 0.028675112 | K7: 0.027374636 | L7: 0.027698618 | M7: 0.028118186 | N7: 0.026408512 | O7: 0.014683914 | P7: 0.014644024 | Q7: 0.013614067 | R7: 0.013194499 | S7: 0.012185452 | T7: 0.011497729 | U7: 0.011093382 | V7: 0.011093398 | W7: 0.0081291107 | X7: 0.0080370316 | Y7: 0.0068360389 | Z7: 0.0095806427 | AA7: 0.0089655761 | AB7: 0.013311272 | AC7: 0.017167204 | AD7: 0.018241911 | AE7: 0.041541548 | AF7: 0.072306945 | AG7: 0.085493838 | AH7: 0.11080152 | AI7: 0.098345426 | AJ7: 0.069950161 | AK7: 0.05528505 | AL7: 0.069916271 | AM7: 0.051517535 | AN7: 0.077478309 | AO7: 0.10897156 | AP7: 0.10943295 | AQ7: 0.11500772 | AR7: 0.10481883 | AS7: 0.10041746 | AT7: 0.10339067 | AU7: 0.10615736
A8: INTL.4419-2-AFG-QBTU.A | B8: Nuclear, renewables, and other (quad Btu) | C8: 0.0024260327 | D8: 0.0024601541 | E8: 0.0024123841 | F8: 0.0025454577 | G8: 0.0025829912 | H8: 0.0026273491 | I8: 0.002432857 | J8: 0.0025795791 | K8: 0.0025386334 | L8: 0.0025591062 | M8: 0.0025795791 | N8: 0.0027569927 | O8: 0.002060915 | P8: 0.0019449066 | Q8: 0.0020302061 | R8: 0.0018152424 | S8: 0.0016071031 | T8: 0.0014399096 | U8: 0.0013648425 | V8: 0.0013648425 | W8: 0.0013887282 | X8: 0.0020233865 | Y8: 0.0022349386 | Z8: 0.0024908492 | AA8: 0.00226906 | AB8: 0.0023714236 | AC8: 0.0036475182 | AD8: 0.0046301899 | AE8: 0.0044152048 | AF8: 0.0065890231 | AG8: 0.008933746 | AH8: 0.011352832 | AI8: 0.012996413 | AJ8: 0.015354808 | AK8: 0.016073391 | AL8: 0.016421761 | AM8: 0.01839936 | AN8: 0.019446166 | AO8: 0.020304949 | AP8: 0.021117049 | AQ8: 0.02117468 | AR8: 0.02261828 | AS8: 0.022942531 | AT8: 0.024123834 | AU8: 0.022843357
A9: INTL.4417-2-AFG-QBTU.A | B9: Nuclear (quad Btu) | C9: 0 | D9: 0 | E9: 0 | F9: 0 | G9: 0 | H9: 0 | I9: 0 | J9: 0 | K9: 0 | L9: 0 | M9: 0 | N9: 0 | O9: 0 | P9: 0 | Q9: 0 | R9: 0 | S9: 0 | T9: 0 | U9: 0 | V9: 0 | W9: 0 | X9: 0 | Y9: 0 | Z9: 0 | AA9: 0 | AB9: 0 | AC9: 0 | AD9: 0 | AE9: 0 | AF9: 0 | AG9: 0 | AH9: 0 | AI9: 0 | AJ9: 0 | AK9: 0 | AL9: 0 | AM9: 0 | AN9: 0 | AO9: 0 | AP9: 0 | AQ9: 0 | AR9: 0 | AS9: 0 | AT9: 0 | AU9: 0
A10: INTL.4418-2-AFG-QBTU.A | B10: Renewables and other (quad Btu) | C10: 0.0024260327 | D10: 0.0024601541 | E10: 0.0024123841 | F10: 0.0025454577 | G10: 0.0025829912 | H10: 0.0026273491 | I10: 0.002432857 | J10: 0.0025795791 | K10: 0.0025386334 | L10: 0.0025591062 | M10: 0.0025795791 | N10: 0.0027569927 | O10: 0.002060915 | P10: 0.0019449066 | Q10: 0.0020302061 | R10: 0.0018152424 | S10: 0.0016071031 | T10: 0.0014399096 | U10: 0.0013648425 | V10: 0.0013648425 | W10: 0.0013887282 | X10: 0.0020233865 | Y10: 0.0022349386 | Z10: 0.0024908492 | AA10: 0.00226906 | AB10: 0.0023714236 | AC10: 0.0036475182 | AD10: 0.0046301899 | AE10: 0.0044152048 | AF10: 0.0065890231 | AG10: 0.008933746 | AH10: 0.011352832 | AI10: 0.012996413 | AJ10: 0.015354808 | AK10: 0.016073391 | AL10: 0.016421761 | AM10: 0.01839936 | AN10: 0.019446166 | AO10: 0.020304949 | AP10: 0.021117049 | AQ10: 0.02117468 | AR10: 0.02261828 | AS10: 0.022942531 | AT10: 0.024123834 | AU10: 0.022843357
B11: Albania
A12: INTL.44-2-ALB-QBTU.A | B12: Consumption (quad Btu) | C12: 0.14261928 | D12: 0.14079517 | E12: 0.14106563 | F12: 0.14682521 | G12: 0.14762843 | H12: 0.1467357 | I12: 0.14240644 | J12: 0.13876024 | K12: 0.14292714 | L12: 0.1333422 | M12: 0.095133926 | N12: 0.071859591 | O12: 0.06210578 | P12: 0.051204863 | Q12: 0.044406117 | R12: 0.048832473 | S12: 0.046068598 | T12: 0.044092001 | U12: 0.050786685 | V12: 0.039812941 | W12: 0.067161628 | X12: 0.068568842 | Y12: 0.077141979 | Z12: 0.079172688 | AA12: 0.085351607 | AB12: 0.084436041 | AC12: 0.080273998 | AD12: 0.078962765 | AE12: 0.081529918 | AF12: 0.08222285 | AG12: 0.075775112 | AH12: 0.081782366 | AI12: 0.07673134 | AJ12: 0.089938222 | AK12: 0.087853264 | AL12: 0.082019821 | AM12: 0.091312362 | AN12: 0.099942583 | AO12: 0.095516638 | AP12: 0.084954345 | AQ12: 0.072063291 | AR12: 0.08698439 | AS12: 0.088269056 | AT12: 0.083192132 | AU12: 0.087328996
A13: INTL.4411-2-ALB-QBTU.A | B13: Coal (quad Btu) | C13: 0.024317315 | D13: 0.025770486 | E13: 0.029070075 | F13: 0.031462709 | G13: 0.033997866 | H13: 0.036247979 | I13: 0.035668553 | J13: 0.037287487 | K13: 0.037487993 | L13: 0.037114724 | M13: 0.032372911 | N13: 0.018421888 | O13: 0.0052350049 | P13: 0.0034656701 | Q13: 0.0028128737 | R13: 0.0021198445 | S13: 0.0016644756 | T13: 0.0012322477 | U13: 0.00075395684 | V13: 0.00090344544 | W13: 0.0010978101 | X13: 0.0012482907 | Y13: 0.00094882682 | Z13: 0.00094876716 | AA13: 0.00090293214 | AB13: 0.00081909191 | AC13: 0.0016219844 | AD13: 0.0023592009 | AE13: 0.0028584824 | AF13: 0.0039230022 | AG13: 0.0035249442 | AH13: 0.0033113417 | AI13: 0.0029688883 | AJ13: 0.0026425202 | AK13: 0.0033396836 | AL13: 0.0028222553 | AM13: 0.0022553832 | AN13: 0.0026038898 | AO13: 0.0034145212 | AP13: 0.0040931699 | AQ13: 0.0046198789 | AR13: 0.0066735653 | AS13: 0.0072524042 | AT13: 0.0057310824 | AU13: 0.0068458282
A14: INTL.4413-2-ALB-QBTU.A | B14: Natural gas (quad Btu) | C14: 0.01047 | D14: 0.011517 | E14: 0.01047 | F14: 0.011517 | G14: 0.011517 | H14: 0.01047 | I14: 0.014658 | J14: 0.016752 | K14: 0.026175 | L14: 0.026175 | M14: 0.0094251534 | N14: 0.00522 | O14: 0.003760488 | P14: 0.001105596 | Q14: 0.00110664 | R14: 0.00110664 | S14: 0.0011060658 | T14: 0.0007373772 | U14: 0.0011060658 | V14: 0.0007373772 | W14: 0.0011060658 | X14: 0.0011060658 | Y14: 0.0011060658 | Z14: 0.0011060658 | AA14: 0.0011060658 | AB14: 0.0011060658 | AC14: 0.0011060658 | AD14: 0.0003644508 | AE14: 0.0010647473 | AF14: 0.0010647473 | AG14: 0.0003503248 | AH14: 0.0003503248 | AI14: 0.00059555216 | AJ14: 0.00066561712 | AK14: 0.0011210394 | AL14: 0.0012261368 | AM14: 0.0015764482 | AN14: 0.0017516091 | AO14: 0.0015036782 | AP14: 0.0027300139 | AQ14: 0.0019624276 | AR14: 0.0020756912 | AS14: 0.0017882392 | AT14: 0.0017591421 | AU14: 0.0019091265
A15: INTL.4415-2-ALB-QBTU.A | B15: Petroleum and other liquids (quad Btu) | C15: 0.099297277 | D15: 0.094720496 | E15: 0.092567758 | F15: 0.094720496 | G15: 0.092821368 | H15: 0.090415019 | I15: 0.082449886 | J15: 0.072966858 | K15: 0.068141514 | L15: 0.058063178 | M15: 0.043014162 | N15: 0.03854419 | O15: 0.043791663 | P15: 0.035639668 | Q15: 0.027742255 | R15: 0.031145343 | S15: 0.024568785 | T15: 0.025573471 | U15: 0.031009561 | V15: 0.01910171 | W15: 0.045761196 | X15: 0.048300987 | Y15: 0.055914566 | Z15: 0.056532534 | AA15: 0.063251986 | AB15: 0.06309585 | AC15: 0.058567703 | AD15: 0.057138346 | AE15: 0.05647564 | AF15: 0.054445616 | AG15: 0.052663621 | AH15: 0.0521623 | AI15: 0.046020699 | AJ15: 0.054955503 | AK15: 0.056805568 | AL15: 0.053080053 | AM15: 0.05483 | AN15: 0.070199116 | AO15: 0.064531253 | AP15: 0.05215828 | AQ15: 0.03958554 | AR15: 0.0496106 | AS15: 0.05229012 | AT15: 0.0481105 | AU15: 0.04898003
